<?xml version="1.0" ?>
<!-- =================================================================================== -->
<!-- |    This document was autogenerated by xacro from /home/fae/catkin_workspace/src/ros_kortex/kortex_description/multiple_robots/kortex_dual_robots.xacro | -->
<!-- |    EDITING THIS FILE BY HAND IS NOT RECOMMENDED                                 | -->
<!-- =================================================================================== -->
<robot name="dual_robot">
    <link name="world" />
    <joint name="world_to_left_root" type="fixed">
        <child link="left_base_link" />
        <parent link="world" />
        <!-- Here you can change the origin of the left arm-->
        <origin rpy="0 0 0" xyz="-1 0 0" />
    </joint>
    <joint name="world_to_right_root" type="fixed">
        <child link="right_base_link" />
        <parent link="world" />
        <!-- Here you can change the origin of the right arm -->
        <origin rpy="0 0 0" xyz="1 0 0" />
    </joint>
    <!-- Run the macros -->
    <link name="left_base_link">
        <inertial>
            <origin rpy="0 0 0" xyz="-0.000648 -0.000166 0.084487" />
            <mass value="1.697" />
            <inertia ixx="0.004622" ixy="9E-06" ixz="6E-05" iyy="0.004495" iyz="9E-06" izz="0.002079" />
        </inertial>
        <visual>
            <origin rpy="0 0 0" xyz="0 0 0" />
            <geometry>
                <mesh filename="package://kortex_description/arms/gen3/6dof/meshes/base_link.STL" />
            </geometry>
            <material name="">
                <color rgba="0.75294 0.75294 0.75294 1" />
            </material>
        </visual>
        <collision>
            <origin rpy="0 0 0" xyz="0 0 0" />
            <geometry>
                <mesh filename="package://kortex_description/arms/gen3/6dof/meshes/base_link.STL" />
            </geometry>
        </collision>
    </link>
    <link name="left_shoulder_link">
        <inertial>
            <origin rpy="0 0 0" xyz="-2.3E-05 -0.010364 -0.07336" />
            <mass value="1.377" />
            <inertia ixx="0.00457" ixy="1E-06" ixz="2E-06" iyy="0.004831" iyz="0.000448" izz="0.001409" />
        </inertial>
        <visual>
            <origin rpy="0 0 0" xyz="0 0 0" />
            <geometry>
                <mesh filename="package://kortex_description/arms/gen3/6dof/meshes/shoulder_link.STL" />
            </geometry>
            <material name="">
                <color rgba="0.75294 0.75294 0.75294 1" />
            </material>
        </visual>
        <collision>
            <origin rpy="0 0 0" xyz="0 0 0" />
            <geometry>
                <mesh filename="package://kortex_description/arms/gen3/6dof/meshes/shoulder_link.STL" />
            </geometry>
        </collision>
    </link>
    <joint name="left_joint_1" type="continuous">
        <origin rpy="-3.1416 0.0 0.0" xyz="0 0 0.15643" />
        <parent link="left_base_link" />
        <child link="left_shoulder_link" />
        <axis xyz="0 0 1" />
        <limit effort="39" velocity="1.3963" />
    </joint>
    <link name="left_bicep_link">
        <inertial>
            <origin rpy="0 0 0" xyz="3.5E-05 -0.208207 -0.01889" />
            <mass value="1.262" />
            <inertia ixx="0.046752" ixy="-9E-06" ixz="0" iyy="0.00085" iyz="-9.8E-05" izz="0.047188" />
        </inertial>
        <visual>
            <origin rpy="0 0 0" xyz="0 0 0" />
            <geometry>
                <mesh filename="package://kortex_description/arms/gen3/6dof/meshes/bicep_link.STL" />
            </geometry>
            <material name="">
                <color rgba="0.75294 0.75294 0.75294 1" />
            </material>
        </visual>
        <collision>
            <origin rpy="0 0 0" xyz="0 0 0" />
            <geometry>
                <mesh filename="package://kortex_description/arms/gen3/6dof/meshes/bicep_link.STL" />
            </geometry>
        </collision>
    </link>
    <joint name="left_joint_2" type="revolute">
        <origin rpy="1.5708 0.0 0.0" xyz="0 0.005375 -0.12838" />
        <parent link="left_shoulder_link" />
        <child link="left_bicep_link" />
        <axis xyz="0 0 1" />
        <limit effort="39" lower="-2.24" upper="2.24" velocity="1.3963" />
    </joint>
    <link name="left_forearm_link">
        <inertial>
            <origin rpy="0 0 0" xyz="1.8E-05 0.076168 -0.01397" />
            <mass value="0.93" />
            <inertia ixx="0.008292" ixy="-1E-06" ixz="0" iyy="0.000628" iyz="0.000432" izz="0.008464" />
        </inertial>
        <visual>
            <origin rpy="0 0 0" xyz="0 0 0" />
            <geometry>
                <mesh filename="package://kortex_description/arms/gen3/6dof/meshes/forearm_link.STL" />
            </geometry>
            <material name="">
                <color rgba="0.75294 0.75294 0.75294 1" />
            </material>
        </visual>
        <collision>
            <origin rpy="0 0 0" xyz="0 0 0" />
            <geometry>
                <mesh filename="package://kortex_description/arms/gen3/6dof/meshes/forearm_link.STL" />
            </geometry>
        </collision>
    </link>
    <joint name="left_joint_3" type="revolute">
        <origin rpy="3.1416 0 0" xyz="0 -0.41 0" />
        <parent link="left_bicep_link" />
        <child link="left_forearm_link" />
        <axis xyz="0 0 1" />
        <limit effort="39" lower="-2.57" upper="2.57" velocity="1.3963" />
    </joint>
    <link name="left_spherical_wrist_1_link">
        <inertial>
            <origin rpy="0 0 0" xyz="-1E-06 0.008486 -0.062937" />
            <mass value="0.6781" />
            <inertia ixx="0.001645" ixy="0" ixz="0" iyy="0.001666" iyz="-0.000234" izz="0.000389" />
        </inertial>
        <visual>
            <origin rpy="0 0 0" xyz="0 0 0" />
            <geometry>
                <mesh filename="package://kortex_description/arms/gen3/6dof/meshes/spherical_wrist_1_link.STL" />
            </geometry>
            <material name="">
                <color rgba="0.75294 0.75294 0.75294 1" />
            </material>
        </visual>
        <collision>
            <origin rpy="0 0 0" xyz="0 0 0" />
            <geometry>
                <mesh filename="package://kortex_description/arms/gen3/6dof/meshes/spherical_wrist_1_link.STL" />
            </geometry>
        </collision>
    </link>
    <joint name="left_joint_4" type="continuous">
        <origin rpy="1.5708 0.0 0.0" xyz="0 0.20843 -0.006375" />
        <parent link="left_forearm_link" />
        <child link="left_spherical_wrist_1_link" />
        <axis xyz="0 0 1" />
        <limit effort="9" velocity="1.2218" />
    </joint>
    <link name="left_spherical_wrist_2_link">
        <inertial>
            <origin rpy="0 0 0" xyz="-1E-06 0.046429 -0.008704" />
            <mass value="0.678" />
            <inertia ixx="0.001685" ixy="0" ixz="0" iyy="0.0004" iyz="0.000255" izz="0.001696" />
        </inertial>
        <visual>
            <origin rpy="0 0 0" xyz="0 0 0" />
            <geometry>
                <mesh filename="package://kortex_description/arms/gen3/6dof/meshes/spherical_wrist_2_link.STL" />
            </geometry>
            <material name="">
                <color rgba="0.75294 0.75294 0.75294 1" />
            </material>
        </visual>
        <collision>
            <origin rpy="0 0 0" xyz="0 0 0" />
            <geometry>
                <mesh filename="package://kortex_description/arms/gen3/6dof/meshes/spherical_wrist_2_link.STL" />
            </geometry>
        </collision>
    </link>
    <joint name="left_joint_5" type="revolute">
        <origin rpy="-1.5708 0.0 0.0" xyz="0 -0.00017505 -0.10593" />
        <parent link="left_spherical_wrist_1_link" />
        <child link="left_spherical_wrist_2_link" />
        <axis xyz="0 0 1" />
        <limit effort="9" lower="-2.09" upper="2.09" velocity="1.2218" />
    </joint>
    <link name="left_bracelet_link">
        <inertial>
            <origin rpy="0 0 0" xyz="0.000281 0.011402 -0.029798" />
            <mass value="0.5" />
            <inertia ixx="0.000587" ixy="3E-06" ixz="3E-06" iyy="0.000369" iyz="-0.000118" izz="0.000609" />
        </inertial>
        <visual>
            <origin rpy="0 0 0" xyz="0 0 0" />
            <geometry>
                <mesh filename="package://kortex_description/arms/gen3/6dof/meshes/bracelet_with_vision_link.STL" />
            </geometry>
            <material name="">
                <color rgba="0.75294 0.75294 0.75294 1" />
            </material>
        </visual>
        <collision>
            <origin rpy="0 0 0" xyz="0 0 0" />
            <geometry>
                <mesh filename="package://kortex_description/arms/gen3/6dof/meshes/bracelet_with_vision_link.STL" />
            </geometry>
        </collision>
    </link>
    <joint name="left_joint_6" type="continuous">
        <origin rpy="1.5708 0.0 0.0" xyz="0 0.10593 -0.00017505" />
        <parent link="left_spherical_wrist_2_link" />
        <child link="left_bracelet_link" />
        <axis xyz="0 0 1" />
        <limit effort="9" velocity="1.2218" />
    </joint>
    <link name="left_end_effector_link" />
    <joint name="left_end_effector" type="fixed">
        <origin rpy="3.14159265358979 1.09937075168372E-32 3.14159265358979" xyz="0 0 -0.0615250000000001" />
        <parent link="left_bracelet_link" />
        <child link="left_end_effector_link" />
        <axis xyz="0 0 0" />
    </joint>
    <link name="left_camera_link" />
    <joint name="left_camera_module" type="fixed">
        <origin rpy="3.14159265358979 3.14159265358979 0" xyz="0 0.05639 -0.00305" />
        <parent link="left_end_effector_link" />
        <child link="left_camera_link" />
    </joint>
    <link name="left_camera_depth_frame" />
    <joint name="left_depth_module" type="fixed">
        <origin rpy="3.14159265358979 3.14159265358979 0" xyz="0.0275 0.066 -0.00305" />
        <parent link="left_end_effector_link" />
        <child link="left_camera_depth_frame" />
    </joint>
    <link name="left_camera_color_frame" />
    <joint name="left_color_module" type="fixed">
        <origin rpy="3.14159265358979 3.14159265358979 0" xyz="0 0.05639 -0.00305" />
        <parent link="left_end_effector_link" />
        <child link="left_camera_color_frame" />
    </joint>
    <link name="left_tool_frame" />
    <joint name="left_tool_frame_joint" type="fixed">
        <origin rpy="0 0 0" xyz="0 0 0" />
        <parent link="left_end_effector_link" />
        <child link="left_tool_frame" />
        <axis xyz="0 0 0" />
    </joint>
    <!-- Run the macros -->
    <link name="right_base_link">
        <inertial>
            <origin rpy="0 0 0" xyz="-0.000648 -0.000166 0.084487" />
            <mass value="1.697" />
            <inertia ixx="0.004622" ixy="9E-06" ixz="6E-05" iyy="0.004495" iyz="9E-06" izz="0.002079" />
        </inertial>
        <visual>
            <origin rpy="0 0 0" xyz="0 0 0" />
            <geometry>
                <mesh filename="package://kortex_description/arms/gen3/6dof/meshes/base_link.STL" />
            </geometry>
            <material name="">
                <color rgba="0.75294 0.75294 0.75294 1" />
            </material>
        </visual>
        <collision>
            <origin rpy="0 0 0" xyz="0 0 0" />
            <geometry>
                <mesh filename="package://kortex_description/arms/gen3/6dof/meshes/base_link.STL" />
            </geometry>
        </collision>
    </link>
    <link name="right_shoulder_link">
        <inertial>
            <origin rpy="0 0 0" xyz="-2.3E-05 -0.010364 -0.07336" />
            <mass value="1.377" />
            <inertia ixx="0.00457" ixy="1E-06" ixz="2E-06" iyy="0.004831" iyz="0.000448" izz="0.001409" />
        </inertial>
        <visual>
            <origin rpy="0 0 0" xyz="0 0 0" />
            <geometry>
                <mesh filename="package://kortex_description/arms/gen3/6dof/meshes/shoulder_link.STL" />
            </geometry>
            <material name="">
                <color rgba="0.75294 0.75294 0.75294 1" />
            </material>
        </visual>
        <collision>
            <origin rpy="0 0 0" xyz="0 0 0" />
            <geometry>
                <mesh filename="package://kortex_description/arms/gen3/6dof/meshes/shoulder_link.STL" />
            </geometry>
        </collision>
    </link>
    <joint name="right_joint_1" type="continuous">
        <origin rpy="-3.1416 0.0 0.0" xyz="0 0 0.15643" />
        <parent link="right_base_link" />
        <child link="right_shoulder_link" />
        <axis xyz="0 0 1" />
        <limit effort="39" velocity="1.3963" />
    </joint>
    <link name="right_bicep_link">
        <inertial>
            <origin rpy="0 0 0" xyz="3.5E-05 -0.208207 -0.01889" />
            <mass value="1.262" />
            <inertia ixx="0.046752" ixy="-9E-06" ixz="0" iyy="0.00085" iyz="-9.8E-05" izz="0.047188" />
        </inertial>
        <visual>
            <origin rpy="0 0 0" xyz="0 0 0" />
            <geometry>
                <mesh filename="package://kortex_description/arms/gen3/6dof/meshes/bicep_link.STL" />
            </geometry>
            <material name="">
                <color rgba="0.75294 0.75294 0.75294 1" />
            </material>
        </visual>
        <collision>
            <origin rpy="0 0 0" xyz="0 0 0" />
            <geometry>
                <mesh filename="package://kortex_description/arms/gen3/6dof/meshes/bicep_link.STL" />
            </geometry>
        </collision>
    </link>
    <joint name="right_joint_2" type="revolute">
        <origin rpy="1.5708 0.0 0.0" xyz="0 0.005375 -0.12838" />
        <parent link="right_shoulder_link" />
        <child link="right_bicep_link" />
        <axis xyz="0 0 1" />
        <limit effort="39" lower="-2.24" upper="2.24" velocity="1.3963" />
    </joint>
    <link name="right_forearm_link">
        <inertial>
            <origin rpy="0 0 0" xyz="1.8E-05 0.076168 -0.01397" />
            <mass value="0.93" />
            <inertia ixx="0.008292" ixy="-1E-06" ixz="0" iyy="0.000628" iyz="0.000432" izz="0.008464" />
        </inertial>
        <visual>
            <origin rpy="0 0 0" xyz="0 0 0" />
            <geometry>
                <mesh filename="package://kortex_description/arms/gen3/6dof/meshes/forearm_link.STL" />
            </geometry>
            <material name="">
                <color rgba="0.75294 0.75294 0.75294 1" />
            </material>
        </visual>
        <collision>
            <origin rpy="0 0 0" xyz="0 0 0" />
            <geometry>
                <mesh filename="package://kortex_description/arms/gen3/6dof/meshes/forearm_link.STL" />
            </geometry>
        </collision>
    </link>
    <joint name="right_joint_3" type="revolute">
        <origin rpy="3.1416 0 0" xyz="0 -0.41 0" />
        <parent link="right_bicep_link" />
        <child link="right_forearm_link" />
        <axis xyz="0 0 1" />
        <limit effort="39" lower="-2.57" upper="2.57" velocity="1.3963" />
    </joint>
    <link name="right_spherical_wrist_1_link">
        <inertial>
            <origin rpy="0 0 0" xyz="-1E-06 0.008486 -0.062937" />
            <mass value="0.6781" />
            <inertia ixx="0.001645" ixy="0" ixz="0" iyy="0.001666" iyz="-0.000234" izz="0.000389" />
        </inertial>
        <visual>
            <origin rpy="0 0 0" xyz="0 0 0" />
            <geometry>
                <mesh filename="package://kortex_description/arms/gen3/6dof/meshes/spherical_wrist_1_link.STL" />
            </geometry>
            <material name="">
                <color rgba="0.75294 0.75294 0.75294 1" />
            </material>
        </visual>
        <collision>
            <origin rpy="0 0 0" xyz="0 0 0" />
            <geometry>
                <mesh filename="package://kortex_description/arms/gen3/6dof/meshes/spherical_wrist_1_link.STL" />
            </geometry>
        </collision>
    </link>
    <joint name="right_joint_4" type="continuous">
        <origin rpy="1.5708 0.0 0.0" xyz="0 0.20843 -0.006375" />
        <parent link="right_forearm_link" />
        <child link="right_spherical_wrist_1_link" />
        <axis xyz="0 0 1" />
        <limit effort="9" velocity="1.2218" />
    </joint>
    <link name="right_spherical_wrist_2_link">
        <inertial>
            <origin rpy="0 0 0" xyz="-1E-06 0.046429 -0.008704" />
            <mass value="0.678" />
            <inertia ixx="0.001685" ixy="0" ixz="0" iyy="0.0004" iyz="0.000255" izz="0.001696" />
        </inertial>
        <visual>
            <origin rpy="0 0 0" xyz="0 0 0" />
            <geometry>
                <mesh filename="package://kortex_description/arms/gen3/6dof/meshes/spherical_wrist_2_link.STL" />
            </geometry>
            <material name="">
                <color rgba="0.75294 0.75294 0.75294 1" />
            </material>
        </visual>
        <collision>
            <origin rpy="0 0 0" xyz="0 0 0" />
            <geometry>
                <mesh filename="package://kortex_description/arms/gen3/6dof/meshes/spherical_wrist_2_link.STL" />
            </geometry>
        </collision>
    </link>
    <joint name="right_joint_5" type="revolute">
        <origin rpy="-1.5708 0.0 0.0" xyz="0 -0.00017505 -0.10593" />
        <parent link="right_spherical_wrist_1_link" />
        <child link="right_spherical_wrist_2_link" />
        <axis xyz="0 0 1" />
        <limit effort="9" lower="-2.09" upper="2.09" velocity="1.2218" />
    </joint>
    <link name="right_bracelet_link">
        <inertial>
            <origin rpy="0 0 0" xyz="0.000281 0.011402 -0.029798" />
            <mass value="0.5" />
            <inertia ixx="0.000587" ixy="3E-06" ixz="3E-06" iyy="0.000369" iyz="-0.000118" izz="0.000609" />
        </inertial>
        <visual>
            <origin rpy="0 0 0" xyz="0 0 0" />
            <geometry>
                <mesh filename="package://kortex_description/arms/gen3/6dof/meshes/bracelet_with_vision_link.STL" />
            </geometry>
            <material name="">
                <color rgba="0.75294 0.75294 0.75294 1" />
            </material>
        </visual>
        <collision>
            <origin rpy="0 0 0" xyz="0 0 0" />
            <geometry>
                <mesh filename="package://kortex_description/arms/gen3/6dof/meshes/bracelet_with_vision_link.STL" />
            </geometry>
        </collision>
    </link>
    <joint name="right_joint_6" type="continuous">
        <origin rpy="1.5708 0.0 0.0" xyz="0 0.10593 -0.00017505" />
        <parent link="right_spherical_wrist_2_link" />
        <child link="right_bracelet_link" />
        <axis xyz="0 0 1" />
        <limit effort="9" velocity="1.2218" />
    </joint>
    <link name="right_end_effector_link" />
    <joint name="right_end_effector" type="fixed">
        <origin rpy="3.14159265358979 1.09937075168372E-32 3.14159265358979" xyz="0 0 -0.0615250000000001" />
        <parent link="right_bracelet_link" />
        <child link="right_end_effector_link" />
        <axis xyz="0 0 0" />
    </joint>
    <link name="right_camera_link" />
    <joint name="right_camera_module" type="fixed">
        <origin rpy="3.14159265358979 3.14159265358979 0" xyz="0 0.05639 -0.00305" />
        <parent link="right_end_effector_link" />
        <child link="right_camera_link" />
    </joint>
    <link name="right_camera_depth_frame" />
    <joint name="right_depth_module" type="fixed">
        <origin rpy="3.14159265358979 3.14159265358979 0" xyz="0.0275 0.066 -0.00305" />
        <parent link="right_end_effector_link" />
        <child link="right_camera_depth_frame" />
    </joint>
    <link name="right_camera_color_frame" />
    <joint name="right_color_module" type="fixed">
        <origin rpy="3.14159265358979 3.14159265358979 0" xyz="0 0.05639 -0.00305" />
        <parent link="right_end_effector_link" />
        <child link="right_camera_color_frame" />
    </joint>
    <link name="right_tool_frame" />
    <joint name="right_tool_frame_joint" type="fixed">
        <origin rpy="0 0 0" xyz="0 0 0" />
        <parent link="right_end_effector_link" />
        <child link="right_tool_frame" />
        <axis xyz="0 0 0" />
    </joint>
    <transmission name="trans_left_joint_1">
        <type>transmission_interface/SimpleTransmission</type>
        <joint name="left_joint_1">
            <hardwareInterface>hardware_interface/EffortJointInterface</hardwareInterface>
        </joint>
        <actuator name="left_joint_1_motor">
            <hardwareInterface>hardware_interface/EffortJointInterface</hardwareInterface>
            <mechanicalReduction>1</mechanicalReduction>
        </actuator>
    </transmission>
    <transmission name="trans_left_joint_2">
        <type>transmission_interface/SimpleTransmission</type>
        <joint name="left_joint_2">
            <hardwareInterface>hardware_interface/EffortJointInterface</hardwareInterface>
        </joint>
        <actuator name="left_joint_2_motor">
            <hardwareInterface>hardware_interface/EffortJointInterface</hardwareInterface>
            <mechanicalReduction>1</mechanicalReduction>
        </actuator>
    </transmission>
    <transmission name="trans_left_joint_3">
        <type>transmission_interface/SimpleTransmission</type>
        <joint name="left_joint_3">
            <hardwareInterface>hardware_interface/EffortJointInterface</hardwareInterface>
        </joint>
        <actuator name="left_joint_3_motor">
            <hardwareInterface>hardware_interface/EffortJointInterface</hardwareInterface>
            <mechanicalReduction>1</mechanicalReduction>
        </actuator>
    </transmission>
    <transmission name="trans_left_joint_4">
        <type>transmission_interface/SimpleTransmission</type>
        <joint name="left_joint_4">
            <hardwareInterface>hardware_interface/EffortJointInterface</hardwareInterface>
        </joint>
        <actuator name="left_joint_4_motor">
            <hardwareInterface>hardware_interface/EffortJointInterface</hardwareInterface>
            <mechanicalReduction>1</mechanicalReduction>
        </actuator>
    </transmission>
    <transmission name="trans_left_joint_5">
        <type>transmission_interface/SimpleTransmission</type>
        <joint name="left_joint_5">
            <hardwareInterface>hardware_interface/EffortJointInterface</hardwareInterface>
        </joint>
        <actuator name="left_joint_5_motor">
            <hardwareInterface>hardware_interface/EffortJointInterface</hardwareInterface>
            <mechanicalReduction>1</mechanicalReduction>
        </actuator>
    </transmission>
    <transmission name="trans_left_joint_6">
        <type>transmission_interface/SimpleTransmission</type>
        <joint name="left_joint_6">
            <hardwareInterface>hardware_interface/EffortJointInterface</hardwareInterface>
        </joint>
        <actuator name="left_joint_6_motor">
            <hardwareInterface>hardware_interface/EffortJointInterface</hardwareInterface>
            <mechanicalReduction>1</mechanicalReduction>
        </actuator>
    </transmission>
    <transmission name="trans_right_joint_1">
        <type>transmission_interface/SimpleTransmission</type>
        <joint name="right_joint_1">
            <hardwareInterface>hardware_interface/EffortJointInterface</hardwareInterface>
        </joint>
        <actuator name="right_joint_1_motor">
            <hardwareInterface>hardware_interface/EffortJointInterface</hardwareInterface>
            <mechanicalReduction>1</mechanicalReduction>
        </actuator>
    </transmission>
    <transmission name="trans_right_joint_2">
        <type>transmission_interface/SimpleTransmission</type>
        <joint name="right_joint_2">
            <hardwareInterface>hardware_interface/EffortJointInterface</hardwareInterface>
        </joint>
        <actuator name="right_joint_2_motor">
            <hardwareInterface>hardware_interface/EffortJointInterface</hardwareInterface>
            <mechanicalReduction>1</mechanicalReduction>
        </actuator>
    </transmission>
    <transmission name="trans_right_joint_3">
        <type>transmission_interface/SimpleTransmission</type>
        <joint name="right_joint_3">
            <hardwareInterface>hardware_interface/EffortJointInterface</hardwareInterface>
        </joint>
        <actuator name="right_joint_3_motor">
            <hardwareInterface>hardware_interface/EffortJointInterface</hardwareInterface>
            <mechanicalReduction>1</mechanicalReduction>
        </actuator>
    </transmission>
    <transmission name="trans_right_joint_4">
        <type>transmission_interface/SimpleTransmission</type>
        <joint name="right_joint_4">
            <hardwareInterface>hardware_interface/EffortJointInterface</hardwareInterface>
        </joint>
        <actuator name="right_joint_4_motor">
            <hardwareInterface>hardware_interface/EffortJointInterface</hardwareInterface>
            <mechanicalReduction>1</mechanicalReduction>
        </actuator>
    </transmission>
    <transmission name="trans_right_joint_5">
        <type>transmission_interface/SimpleTransmission</type>
        <joint name="right_joint_5">
            <hardwareInterface>hardware_interface/EffortJointInterface</hardwareInterface>
        </joint>
        <actuator name="right_joint_5_motor">
            <hardwareInterface>hardware_interface/EffortJointInterface</hardwareInterface>
            <mechanicalReduction>1</mechanicalReduction>
        </actuator>
    </transmission>
    <transmission name="trans_right_joint_6">
        <type>transmission_interface/SimpleTransmission</type>
        <joint name="right_joint_6">
            <hardwareInterface>hardware_interface/EffortJointInterface</hardwareInterface>
        </joint>
        <actuator name="right_joint_6_motor">
            <hardwareInterface>hardware_interface/EffortJointInterface</hardwareInterface>
            <mechanicalReduction>1</mechanicalReduction>
        </actuator>
    </transmission>
    <gazebo>
        <plugin name="gazebo_ros_control" filename="libgazebo_ros_control.so">
            <robotNamespace>/</robotNamespace>
        </plugin>
    </gazebo>
</robot>

